[2024-08-30T17:00:16.273+0000] {taskinstance.py:1956} INFO - Dependencies all met for dep_context=non-requeueable deps ti=<TaskInstance: ETL_Dag_S3.detect_new_or_changed_rows scheduled__2024-08-30T16:00:00+00:00 [queued]>
[2024-08-30T17:00:16.325+0000] {taskinstance.py:1956} INFO - Dependencies all met for dep_context=requeueable deps ti=<TaskInstance: ETL_Dag_S3.detect_new_or_changed_rows scheduled__2024-08-30T16:00:00+00:00 [queued]>
[2024-08-30T17:00:16.327+0000] {taskinstance.py:2170} INFO - Starting attempt 1 of 6
[2024-08-30T17:00:16.431+0000] {taskinstance.py:2191} INFO - Executing <Task(_PythonDecoratedOperator): detect_new_or_changed_rows> on 2024-08-30 16:00:00+00:00
[2024-08-30T17:00:16.453+0000] {standard_task_runner.py:60} INFO - Started process 293 to run task
[2024-08-30T17:00:16.461+0000] {standard_task_runner.py:87} INFO - Running: ['***', 'tasks', 'run', 'ETL_Dag_S3', 'detect_new_or_changed_rows', 'scheduled__2024-08-30T16:00:00+00:00', '--job-id', '103', '--raw', '--subdir', 'DAGS_FOLDER/etl_dag_s3.py', '--cfg-path', '/tmp/tmpe6jo1db2']
[2024-08-30T17:00:16.478+0000] {standard_task_runner.py:88} INFO - Job 103: Subtask detect_new_or_changed_rows
[2024-08-30T17:00:16.697+0000] {task_command.py:423} INFO - Running <TaskInstance: ETL_Dag_S3.detect_new_or_changed_rows scheduled__2024-08-30T16:00:00+00:00 [running]> on host 3f05e13fdaf7
[2024-08-30T17:00:16.998+0000] {taskinstance.py:2480} INFO - Exporting env vars: AIRFLOW_CTX_DAG_OWNER='jasontran' AIRFLOW_CTX_DAG_ID='ETL_Dag_S3' AIRFLOW_CTX_TASK_ID='detect_new_or_changed_rows' AIRFLOW_CTX_EXECUTION_DATE='2024-08-30T16:00:00+00:00' AIRFLOW_CTX_TRY_NUMBER='1' AIRFLOW_CTX_DAG_RUN_ID='scheduled__2024-08-30T16:00:00+00:00'
[2024-08-30T17:00:17.033+0000] {credentials.py:1147} INFO - Found credentials in environment variables.
[2024-08-30T17:00:18.008+0000] {logging_mixin.py:188} INFO - Succesfully read data from AWS S3
[2024-08-30T17:00:18.017+0000] {connection.py:370} INFO - Snowflake Connector for Python Version: 3.6.0, Python Version: 3.8.18, Platform: Linux-5.15.146.1-microsoft-standard-WSL2-x86_64-with-glibc2.34
[2024-08-30T17:00:18.041+0000] {taskinstance.py:2698} ERROR - Task failed with exception
Traceback (most recent call last):
  File "/home/airflow/.local/lib/python3.8/site-packages/airflow/models/taskinstance.py", line 433, in _execute_task
    result = execute_callable(context=context, **execute_callable_kwargs)
  File "/home/airflow/.local/lib/python3.8/site-packages/airflow/decorators/base.py", line 241, in execute
    return_value = super().execute(context)
  File "/home/airflow/.local/lib/python3.8/site-packages/airflow/operators/python.py", line 199, in execute
    return_value = self.execute_callable()
  File "/home/airflow/.local/lib/python3.8/site-packages/airflow/operators/python.py", line 216, in execute_callable
    return self.python_callable(*self.op_args, **self.op_kwargs)
  File "/opt/airflow/includes/emp_dim_insert_update.py", line 27, in detect_new_or_changed_rows
    conn = sc.connect(
  File "/home/airflow/.local/lib/python3.8/site-packages/snowflake/connector/__init__.py", line 54, in Connect
    return SnowflakeConnection(**kwargs)
  File "/home/airflow/.local/lib/python3.8/site-packages/snowflake/connector/connection.py", line 413, in __init__
    self.connect(**kwargs)
  File "/home/airflow/.local/lib/python3.8/site-packages/snowflake/connector/connection.py", line 667, in connect
    self.__config(**kwargs)
  File "/home/airflow/.local/lib/python3.8/site-packages/snowflake/connector/connection.py", line 1140, in __config
    Error.errorhandler_wrapper(
  File "/home/airflow/.local/lib/python3.8/site-packages/snowflake/connector/errors.py", line 290, in errorhandler_wrapper
    handed_over = Error.hand_to_other_handler(
  File "/home/airflow/.local/lib/python3.8/site-packages/snowflake/connector/errors.py", line 348, in hand_to_other_handler
    connection.errorhandler(connection, cursor, error_class, error_value)
  File "/home/airflow/.local/lib/python3.8/site-packages/snowflake/connector/errors.py", line 221, in default_errorhandler
    raise error_class(
snowflake.connector.errors.ProgrammingError: 251006: 251006: Password is empty
[2024-08-30T17:00:18.061+0000] {taskinstance.py:1138} INFO - Marking task as UP_FOR_RETRY. dag_id=ETL_Dag_S3, task_id=detect_new_or_changed_rows, execution_date=20240830T160000, start_date=20240830T170016, end_date=20240830T170018
[2024-08-30T17:00:18.094+0000] {standard_task_runner.py:107} ERROR - Failed to execute job 103 for task detect_new_or_changed_rows (251006: 251006: Password is empty; 293)
[2024-08-30T17:00:18.130+0000] {local_task_job_runner.py:234} INFO - Task exited with return code 1
[2024-08-30T17:00:18.190+0000] {taskinstance.py:3280} INFO - 0 downstream tasks scheduled from follow-on schedule check
