[2024-09-14T15:15:28.890+0000] {taskinstance.py:1956} INFO - Dependencies all met for dep_context=non-requeueable deps ti=<TaskInstance: ETL_Dag_S3.snowflake_update_task scheduled__2024-09-13T00:00:00+00:00 [queued]>
[2024-09-14T15:15:28.910+0000] {taskinstance.py:1956} INFO - Dependencies all met for dep_context=requeueable deps ti=<TaskInstance: ETL_Dag_S3.snowflake_update_task scheduled__2024-09-13T00:00:00+00:00 [queued]>
[2024-09-14T15:15:28.912+0000] {taskinstance.py:2170} INFO - Starting attempt 3 of 8
[2024-09-14T15:15:28.938+0000] {taskinstance.py:2191} INFO - Executing <Task(SnowflakeOperator): snowflake_update_task> on 2024-09-13 00:00:00+00:00
[2024-09-14T15:15:28.949+0000] {standard_task_runner.py:60} INFO - Started process 1402 to run task
[2024-09-14T15:15:28.955+0000] {standard_task_runner.py:87} INFO - Running: ['***', 'tasks', 'run', 'ETL_Dag_S3', 'snowflake_update_task', 'scheduled__2024-09-13T00:00:00+00:00', '--job-id', '14', '--raw', '--subdir', 'DAGS_FOLDER/etl_dag_s3.py', '--cfg-path', '/tmp/tmpt_v7aebr']
[2024-09-14T15:15:28.959+0000] {standard_task_runner.py:88} INFO - Job 14: Subtask snowflake_update_task
[2024-09-14T15:15:29.038+0000] {task_command.py:423} INFO - Running <TaskInstance: ETL_Dag_S3.snowflake_update_task scheduled__2024-09-13T00:00:00+00:00 [running]> on host 12663b3bf2f5
[2024-09-14T15:15:29.203+0000] {taskinstance.py:2480} INFO - Exporting env vars: AIRFLOW_CTX_DAG_OWNER='jasontran' AIRFLOW_CTX_DAG_ID='ETL_Dag_S3' AIRFLOW_CTX_TASK_ID='snowflake_update_task' AIRFLOW_CTX_EXECUTION_DATE='2024-09-13T00:00:00+00:00' AIRFLOW_CTX_TRY_NUMBER='3' AIRFLOW_CTX_DAG_RUN_ID='scheduled__2024-09-13T00:00:00+00:00'
[2024-09-14T15:15:29.205+0000] {sql.py:276} INFO - Executing: 
    update ***_db.tcops_dimensions.employee_dim
    set effective_end_date = '2024-09-14', is_active = 'N'
    where employee_id in ('950018', '001826') and is_active = 'Y'
    
[2024-09-14T15:15:29.227+0000] {base.py:83} INFO - Using connection ID 'snowflake_conn' for task execution.
[2024-09-14T15:15:29.253+0000] {base.py:83} INFO - Using connection ID 'snowflake_conn' for task execution.
[2024-09-14T15:15:29.255+0000] {connection.py:370} INFO - Snowflake Connector for Python Version: 3.6.0, Python Version: 3.8.18, Platform: Linux-5.15.146.1-microsoft-standard-WSL2-x86_64-with-glibc2.34
[2024-09-14T15:15:29.275+0000] {taskinstance.py:2698} ERROR - Task failed with exception
Traceback (most recent call last):
  File "/home/airflow/.local/lib/python3.8/site-packages/airflow/models/taskinstance.py", line 433, in _execute_task
    result = execute_callable(context=context, **execute_callable_kwargs)
  File "/home/airflow/.local/lib/python3.8/site-packages/airflow/providers/common/sql/operators/sql.py", line 282, in execute
    output = hook.run(
  File "/home/airflow/.local/lib/python3.8/site-packages/airflow/providers/snowflake/hooks/snowflake.py", line 382, in run
    with closing(self.get_conn()) as conn:
  File "/home/airflow/.local/lib/python3.8/site-packages/airflow/providers/snowflake/hooks/snowflake.py", line 276, in get_conn
    conn = connector.connect(**conn_config)
  File "/home/airflow/.local/lib/python3.8/site-packages/snowflake/connector/__init__.py", line 54, in Connect
    return SnowflakeConnection(**kwargs)
  File "/home/airflow/.local/lib/python3.8/site-packages/snowflake/connector/connection.py", line 413, in __init__
    self.connect(**kwargs)
  File "/home/airflow/.local/lib/python3.8/site-packages/snowflake/connector/connection.py", line 667, in connect
    self.__config(**kwargs)
  File "/home/airflow/.local/lib/python3.8/site-packages/snowflake/connector/connection.py", line 1120, in __config
    Error.errorhandler_wrapper(
  File "/home/airflow/.local/lib/python3.8/site-packages/snowflake/connector/errors.py", line 290, in errorhandler_wrapper
    handed_over = Error.hand_to_other_handler(
  File "/home/airflow/.local/lib/python3.8/site-packages/snowflake/connector/errors.py", line 348, in hand_to_other_handler
    connection.errorhandler(connection, cursor, error_class, error_value)
  File "/home/airflow/.local/lib/python3.8/site-packages/snowflake/connector/errors.py", line 221, in default_errorhandler
    raise error_class(
snowflake.connector.errors.ProgrammingError: 251005: 251005: User is empty
[2024-09-14T15:15:29.296+0000] {taskinstance.py:1138} INFO - Marking task as UP_FOR_RETRY. dag_id=ETL_Dag_S3, task_id=snowflake_update_task, execution_date=20240913T000000, start_date=20240914T151528, end_date=20240914T151529
[2024-09-14T15:15:29.325+0000] {standard_task_runner.py:107} ERROR - Failed to execute job 14 for task snowflake_update_task (251005: 251005: User is empty; 1402)
[2024-09-14T15:15:29.369+0000] {local_task_job_runner.py:234} INFO - Task exited with return code 1
[2024-09-14T15:15:29.422+0000] {taskinstance.py:3280} INFO - 0 downstream tasks scheduled from follow-on schedule check
