[2024-08-29T17:00:24.834+0000] {taskinstance.py:1956} INFO - Dependencies all met for dep_context=non-requeueable deps ti=<TaskInstance: ETL_Dag_S3.detect_new_or_changed_rows scheduled__2024-08-29T15:00:00+00:00 [queued]>
[2024-08-29T17:00:24.849+0000] {taskinstance.py:1956} INFO - Dependencies all met for dep_context=requeueable deps ti=<TaskInstance: ETL_Dag_S3.detect_new_or_changed_rows scheduled__2024-08-29T15:00:00+00:00 [queued]>
[2024-08-29T17:00:24.850+0000] {taskinstance.py:2170} INFO - Starting attempt 5 of 7
[2024-08-29T17:00:24.875+0000] {taskinstance.py:2191} INFO - Executing <Task(_PythonDecoratedOperator): detect_new_or_changed_rows> on 2024-08-29 15:00:00+00:00
[2024-08-29T17:00:24.884+0000] {standard_task_runner.py:60} INFO - Started process 1454 to run task
[2024-08-29T17:00:24.888+0000] {standard_task_runner.py:87} INFO - Running: ['***', 'tasks', 'run', 'ETL_Dag_S3', 'detect_new_or_changed_rows', 'scheduled__2024-08-29T15:00:00+00:00', '--job-id', '47', '--raw', '--subdir', 'DAGS_FOLDER/etl_dag_s3.py', '--cfg-path', '/tmp/tmpgz2jilj5']
[2024-08-29T17:00:24.892+0000] {standard_task_runner.py:88} INFO - Job 47: Subtask detect_new_or_changed_rows
[2024-08-29T17:00:24.966+0000] {task_command.py:423} INFO - Running <TaskInstance: ETL_Dag_S3.detect_new_or_changed_rows scheduled__2024-08-29T15:00:00+00:00 [running]> on host 77c04f75763c
[2024-08-29T17:00:25.176+0000] {taskinstance.py:2480} INFO - Exporting env vars: AIRFLOW_CTX_DAG_OWNER='jasontran' AIRFLOW_CTX_DAG_ID='ETL_Dag_S3' AIRFLOW_CTX_TASK_ID='detect_new_or_changed_rows' AIRFLOW_CTX_EXECUTION_DATE='2024-08-29T15:00:00+00:00' AIRFLOW_CTX_TRY_NUMBER='5' AIRFLOW_CTX_DAG_RUN_ID='scheduled__2024-08-29T15:00:00+00:00'
[2024-08-29T17:00:26.218+0000] {taskinstance.py:2698} ERROR - Task failed with exception
Traceback (most recent call last):
  File "/home/airflow/.local/lib/python3.8/site-packages/s3fs/core.py", line 113, in _error_wrapper
    return await func(*args, **kwargs)
  File "/home/airflow/.local/lib/python3.8/site-packages/aiobotocore/client.py", line 408, in _make_api_call
    raise error_class(parsed_response, operation_name)
botocore.exceptions.ClientError: An error occurred (403) when calling the HeadObject operation: Forbidden

The above exception was the direct cause of the following exception:

Traceback (most recent call last):
  File "/home/airflow/.local/lib/python3.8/site-packages/airflow/models/taskinstance.py", line 433, in _execute_task
    result = execute_callable(context=context, **execute_callable_kwargs)
  File "/home/airflow/.local/lib/python3.8/site-packages/airflow/decorators/base.py", line 241, in execute
    return_value = super().execute(context)
  File "/home/airflow/.local/lib/python3.8/site-packages/airflow/operators/python.py", line 199, in execute
    return_value = self.execute_callable()
  File "/home/airflow/.local/lib/python3.8/site-packages/airflow/operators/python.py", line 216, in execute_callable
    return self.python_callable(*self.op_args, **self.op_kwargs)
  File "/opt/airflow/includes/emp_dim_insert_update.py", line 19, in detect_new_or_changed_rows
    emp_detail = pd.read_csv('s3://etl-airflow-bucket-demo/Jason_emp_data.csv')
  File "/home/airflow/.local/lib/python3.8/site-packages/pandas/io/parsers/readers.py", line 912, in read_csv
    return _read(filepath_or_buffer, kwds)
  File "/home/airflow/.local/lib/python3.8/site-packages/pandas/io/parsers/readers.py", line 577, in _read
    parser = TextFileReader(filepath_or_buffer, **kwds)
  File "/home/airflow/.local/lib/python3.8/site-packages/pandas/io/parsers/readers.py", line 1407, in __init__
    self._engine = self._make_engine(f, self.engine)
  File "/home/airflow/.local/lib/python3.8/site-packages/pandas/io/parsers/readers.py", line 1661, in _make_engine
    self.handles = get_handle(
  File "/home/airflow/.local/lib/python3.8/site-packages/pandas/io/common.py", line 716, in get_handle
    ioargs = _get_filepath_or_buffer(
  File "/home/airflow/.local/lib/python3.8/site-packages/pandas/io/common.py", line 425, in _get_filepath_or_buffer
    file_obj = fsspec.open(
  File "/home/airflow/.local/lib/python3.8/site-packages/fsspec/core.py", line 147, in open
    return self.__enter__()
  File "/home/airflow/.local/lib/python3.8/site-packages/fsspec/core.py", line 105, in __enter__
    f = self.fs.open(self.path, mode=mode)
  File "/home/airflow/.local/lib/python3.8/site-packages/fsspec/spec.py", line 1303, in open
    f = self._open(
  File "/home/airflow/.local/lib/python3.8/site-packages/s3fs/core.py", line 688, in _open
    return S3File(
  File "/home/airflow/.local/lib/python3.8/site-packages/s3fs/core.py", line 2182, in __init__
    super().__init__(
  File "/home/airflow/.local/lib/python3.8/site-packages/fsspec/spec.py", line 1742, in __init__
    self.size = self.details["size"]
  File "/home/airflow/.local/lib/python3.8/site-packages/fsspec/spec.py", line 1755, in details
    self._details = self.fs.info(self.path)
  File "/home/airflow/.local/lib/python3.8/site-packages/fsspec/asyn.py", line 118, in wrapper
    return sync(self.loop, func, *args, **kwargs)
  File "/home/airflow/.local/lib/python3.8/site-packages/fsspec/asyn.py", line 103, in sync
    raise return_result
  File "/home/airflow/.local/lib/python3.8/site-packages/fsspec/asyn.py", line 56, in _runner
    result[0] = await coro
  File "/home/airflow/.local/lib/python3.8/site-packages/s3fs/core.py", line 1374, in _info
    out = await self._call_s3(
  File "/home/airflow/.local/lib/python3.8/site-packages/s3fs/core.py", line 365, in _call_s3
    return await _error_wrapper(
  File "/home/airflow/.local/lib/python3.8/site-packages/s3fs/core.py", line 145, in _error_wrapper
    raise err
PermissionError: Forbidden
[2024-08-29T17:00:26.241+0000] {taskinstance.py:1138} INFO - Marking task as UP_FOR_RETRY. dag_id=ETL_Dag_S3, task_id=detect_new_or_changed_rows, execution_date=20240829T150000, start_date=20240829T170024, end_date=20240829T170026
[2024-08-29T17:00:26.268+0000] {standard_task_runner.py:107} ERROR - Failed to execute job 47 for task detect_new_or_changed_rows (Forbidden; 1454)
[2024-08-29T17:00:26.306+0000] {local_task_job_runner.py:234} INFO - Task exited with return code 1
[2024-08-29T17:00:26.368+0000] {taskinstance.py:3280} INFO - 0 downstream tasks scheduled from follow-on schedule check
