[2024-09-12T17:02:11.436+0000] {taskinstance.py:1956} INFO - Dependencies all met for dep_context=non-requeueable deps ti=<TaskInstance: ETL_Dag_S3.extract_hr scheduled__2024-09-11T00:00:00+00:00 [queued]>
[2024-09-12T17:02:11.470+0000] {taskinstance.py:1956} INFO - Dependencies all met for dep_context=requeueable deps ti=<TaskInstance: ETL_Dag_S3.extract_hr scheduled__2024-09-11T00:00:00+00:00 [queued]>
[2024-09-12T17:02:11.472+0000] {taskinstance.py:2170} INFO - Starting attempt 4 of 9
[2024-09-12T17:02:11.512+0000] {taskinstance.py:2191} INFO - Executing <Task(SqlToS3Operator): extract_hr> on 2024-09-11 00:00:00+00:00
[2024-09-12T17:02:11.521+0000] {standard_task_runner.py:60} INFO - Started process 706 to run task
[2024-09-12T17:02:11.529+0000] {standard_task_runner.py:87} INFO - Running: ['***', 'tasks', 'run', 'ETL_Dag_S3', 'extract_hr', 'scheduled__2024-09-11T00:00:00+00:00', '--job-id', '5', '--raw', '--subdir', 'DAGS_FOLDER/etl_dag_s3.py', '--cfg-path', '/tmp/tmpbh5pm4k_']
[2024-09-12T17:02:11.539+0000] {standard_task_runner.py:88} INFO - Job 5: Subtask extract_hr
[2024-09-12T17:02:11.660+0000] {task_command.py:423} INFO - Running <TaskInstance: ETL_Dag_S3.extract_hr scheduled__2024-09-11T00:00:00+00:00 [running]> on host 8ebc76993c69
[2024-09-12T17:02:11.811+0000] {taskinstance.py:2480} INFO - Exporting env vars: AIRFLOW_CTX_DAG_OWNER='jasontran' AIRFLOW_CTX_DAG_ID='ETL_Dag_S3' AIRFLOW_CTX_TASK_ID='extract_hr' AIRFLOW_CTX_EXECUTION_DATE='2024-09-11T00:00:00+00:00' AIRFLOW_CTX_TRY_NUMBER='4' AIRFLOW_CTX_DAG_RUN_ID='scheduled__2024-09-11T00:00:00+00:00'
[2024-09-12T17:02:11.831+0000] {base.py:83} INFO - Using connection ID 'PostgreSQL_conn' for task execution.
[2024-09-12T17:02:11.851+0000] {base.py:83} INFO - Using connection ID 'PostgreSQL_conn' for task execution.
[2024-09-12T17:02:11.854+0000] {taskinstance.py:2698} ERROR - Task failed with exception
Traceback (most recent call last):
  File "/home/airflow/.local/lib/python3.8/site-packages/airflow/models/taskinstance.py", line 433, in _execute_task
    result = execute_callable(context=context, **execute_callable_kwargs)
  File "/home/airflow/.local/lib/python3.8/site-packages/airflow/providers/amazon/aws/transfers/sql_to_s3.py", line 178, in execute
    data_df = sql_hook.get_pandas_df(sql=self.query, parameters=self.parameters)
  File "/home/airflow/.local/lib/python3.8/site-packages/airflow/providers/common/sql/hooks/sql.py", line 220, in get_pandas_df
    with closing(self.get_conn()) as conn:
  File "/home/airflow/.local/lib/python3.8/site-packages/airflow/providers/postgres/hooks/postgres.py", line 158, in get_conn
    self.conn = psycopg2.connect(**conn_args)
  File "/home/airflow/.local/lib/python3.8/site-packages/psycopg2/__init__.py", line 121, in connect
    dsn = _ext.make_dsn(dsn, **kwargs)
  File "/home/airflow/.local/lib/python3.8/site-packages/psycopg2/extensions.py", line 167, in make_dsn
    parse_dsn(dsn)
psycopg2.ProgrammingError: invalid dsn: invalid connection option "login"

[2024-09-12T17:02:11.876+0000] {taskinstance.py:1138} INFO - Marking task as UP_FOR_RETRY. dag_id=ETL_Dag_S3, task_id=extract_hr, execution_date=20240911T000000, start_date=20240912T170211, end_date=20240912T170211
[2024-09-12T17:02:11.915+0000] {standard_task_runner.py:107} ERROR - Failed to execute job 5 for task extract_hr (invalid dsn: invalid connection option "login"
; 706)
[2024-09-12T17:02:11.945+0000] {local_task_job_runner.py:234} INFO - Task exited with return code 1
[2024-09-12T17:02:12.003+0000] {taskinstance.py:3280} INFO - 0 downstream tasks scheduled from follow-on schedule check
