[2024-08-31T16:50:46.218+0000] {taskinstance.py:1956} INFO - Dependencies all met for dep_context=non-requeueable deps ti=<TaskInstance: ETL_Dag_S3.detect_new_or_changed_rows scheduled__2024-08-30T00:00:00+00:00 [queued]>
[2024-08-31T16:50:46.262+0000] {taskinstance.py:1956} INFO - Dependencies all met for dep_context=requeueable deps ti=<TaskInstance: ETL_Dag_S3.detect_new_or_changed_rows scheduled__2024-08-30T00:00:00+00:00 [queued]>
[2024-08-31T16:50:46.274+0000] {taskinstance.py:2170} INFO - Starting attempt 15 of 20
[2024-08-31T16:50:46.342+0000] {taskinstance.py:2191} INFO - Executing <Task(_PythonDecoratedOperator): detect_new_or_changed_rows> on 2024-08-30 00:00:00+00:00
[2024-08-31T16:50:46.377+0000] {standard_task_runner.py:60} INFO - Started process 4904 to run task
[2024-08-31T16:50:46.454+0000] {standard_task_runner.py:87} INFO - Running: ['***', 'tasks', 'run', 'ETL_Dag_S3', 'detect_new_or_changed_rows', 'scheduled__2024-08-30T00:00:00+00:00', '--job-id', '241', '--raw', '--subdir', 'DAGS_FOLDER/etl_dag_s3.py', '--cfg-path', '/tmp/tmprxb36i89']
[2024-08-31T16:50:46.469+0000] {standard_task_runner.py:88} INFO - Job 241: Subtask detect_new_or_changed_rows
[2024-08-31T16:50:46.670+0000] {task_command.py:423} INFO - Running <TaskInstance: ETL_Dag_S3.detect_new_or_changed_rows scheduled__2024-08-30T00:00:00+00:00 [running]> on host b5c60e3907e4
[2024-08-31T16:50:47.124+0000] {taskinstance.py:2480} INFO - Exporting env vars: AIRFLOW_CTX_DAG_OWNER='jasontran' AIRFLOW_CTX_DAG_ID='ETL_Dag_S3' AIRFLOW_CTX_TASK_ID='detect_new_or_changed_rows' AIRFLOW_CTX_EXECUTION_DATE='2024-08-30T00:00:00+00:00' AIRFLOW_CTX_TRY_NUMBER='15' AIRFLOW_CTX_DAG_RUN_ID='scheduled__2024-08-30T00:00:00+00:00'
[2024-08-31T16:50:47.204+0000] {credentials.py:1147} INFO - Found credentials in environment variables.
[2024-08-31T16:50:49.055+0000] {logging_mixin.py:188} INFO - Succesfully read data from AWS S3
[2024-08-31T16:50:49.062+0000] {taskinstance.py:2698} ERROR - Task failed with exception
Traceback (most recent call last):
  File "/home/airflow/.local/lib/python3.8/site-packages/airflow/models/taskinstance.py", line 433, in _execute_task
    result = execute_callable(context=context, **execute_callable_kwargs)
  File "/home/airflow/.local/lib/python3.8/site-packages/airflow/decorators/base.py", line 241, in execute
    return_value = super().execute(context)
  File "/home/airflow/.local/lib/python3.8/site-packages/airflow/operators/python.py", line 199, in execute
    return_value = self.execute_callable()
  File "/home/airflow/.local/lib/python3.8/site-packages/airflow/operators/python.py", line 216, in execute_callable
    return self.python_callable(*self.op_args, **self.op_kwargs)
  File "/opt/airflow/includes/emp_dim_insert_update.py", line 34, in detect_new_or_changed_rows
    src_emp_df = src_emp_df.map(lambda x: escape_single_quotes(x))
  File "/home/airflow/.local/lib/python3.8/site-packages/pandas/core/generic.py", line 5989, in __getattr__
    return object.__getattribute__(self, name)
AttributeError: 'DataFrame' object has no attribute 'map'
[2024-08-31T16:50:49.111+0000] {taskinstance.py:1138} INFO - Marking task as UP_FOR_RETRY. dag_id=ETL_Dag_S3, task_id=detect_new_or_changed_rows, execution_date=20240830T000000, start_date=20240831T165046, end_date=20240831T165049
[2024-08-31T16:50:49.179+0000] {standard_task_runner.py:107} ERROR - Failed to execute job 241 for task detect_new_or_changed_rows ('DataFrame' object has no attribute 'map'; 4904)
[2024-08-31T16:50:49.239+0000] {local_task_job_runner.py:234} INFO - Task exited with return code 1
[2024-08-31T16:50:49.341+0000] {taskinstance.py:3280} INFO - 0 downstream tasks scheduled from follow-on schedule check
