[2024-08-31T13:45:49.965+0000] {taskinstance.py:1956} INFO - Dependencies all met for dep_context=non-requeueable deps ti=<TaskInstance: ETL_Dag_S3.detect_new_or_changed_rows scheduled__2024-08-30T00:00:00+00:00 [queued]>
[2024-08-31T13:45:49.983+0000] {taskinstance.py:1956} INFO - Dependencies all met for dep_context=requeueable deps ti=<TaskInstance: ETL_Dag_S3.detect_new_or_changed_rows scheduled__2024-08-30T00:00:00+00:00 [queued]>
[2024-08-31T13:45:49.984+0000] {taskinstance.py:2170} INFO - Starting attempt 8 of 13
[2024-08-31T13:45:50.022+0000] {taskinstance.py:2191} INFO - Executing <Task(_PythonDecoratedOperator): detect_new_or_changed_rows> on 2024-08-30 00:00:00+00:00
[2024-08-31T13:45:50.031+0000] {standard_task_runner.py:60} INFO - Started process 4692 to run task
[2024-08-31T13:45:50.038+0000] {standard_task_runner.py:87} INFO - Running: ['***', 'tasks', 'run', 'ETL_Dag_S3', 'detect_new_or_changed_rows', 'scheduled__2024-08-30T00:00:00+00:00', '--job-id', '200', '--raw', '--subdir', 'DAGS_FOLDER/etl_dag_s3.py', '--cfg-path', '/tmp/tmpu9rewh1e']
[2024-08-31T13:45:50.042+0000] {standard_task_runner.py:88} INFO - Job 200: Subtask detect_new_or_changed_rows
[2024-08-31T13:45:50.123+0000] {task_command.py:423} INFO - Running <TaskInstance: ETL_Dag_S3.detect_new_or_changed_rows scheduled__2024-08-30T00:00:00+00:00 [running]> on host 3253e99ed5f2
[2024-08-31T13:45:50.283+0000] {taskinstance.py:2480} INFO - Exporting env vars: AIRFLOW_CTX_DAG_OWNER='jasontran' AIRFLOW_CTX_DAG_ID='ETL_Dag_S3' AIRFLOW_CTX_TASK_ID='detect_new_or_changed_rows' AIRFLOW_CTX_EXECUTION_DATE='2024-08-30T00:00:00+00:00' AIRFLOW_CTX_TRY_NUMBER='8' AIRFLOW_CTX_DAG_RUN_ID='scheduled__2024-08-30T00:00:00+00:00'
[2024-08-31T13:45:50.317+0000] {credentials.py:1147} INFO - Found credentials in environment variables.
[2024-08-31T13:45:51.045+0000] {taskinstance.py:2698} ERROR - Task failed with exception
Traceback (most recent call last):
  File "/home/airflow/.local/lib/python3.8/site-packages/airflow/models/taskinstance.py", line 433, in _execute_task
    result = execute_callable(context=context, **execute_callable_kwargs)
  File "/home/airflow/.local/lib/python3.8/site-packages/airflow/decorators/base.py", line 241, in execute
    return_value = super().execute(context)
  File "/home/airflow/.local/lib/python3.8/site-packages/airflow/operators/python.py", line 199, in execute
    return_value = self.execute_callable()
  File "/home/airflow/.local/lib/python3.8/site-packages/airflow/operators/python.py", line 216, in execute_callable
    return self.python_callable(*self.op_args, **self.op_kwargs)
  File "/opt/airflow/includes/emp_dim_insert_update.py", line 17, in detect_new_or_changed_rows
    emp_detail.drop(emp_detail.columns[0], axit=1, inplace=True)
TypeError: drop() got an unexpected keyword argument 'axit'
[2024-08-31T13:45:51.068+0000] {taskinstance.py:1138} INFO - Marking task as UP_FOR_RETRY. dag_id=ETL_Dag_S3, task_id=detect_new_or_changed_rows, execution_date=20240830T000000, start_date=20240831T134549, end_date=20240831T134551
[2024-08-31T13:45:51.094+0000] {standard_task_runner.py:107} ERROR - Failed to execute job 200 for task detect_new_or_changed_rows (drop() got an unexpected keyword argument 'axit'; 4692)
[2024-08-31T13:45:51.135+0000] {local_task_job_runner.py:234} INFO - Task exited with return code 1
[2024-08-31T13:45:51.200+0000] {taskinstance.py:3280} INFO - 0 downstream tasks scheduled from follow-on schedule check
