[2024-09-13T15:26:01.412+0000] {taskinstance.py:1956} INFO - Dependencies all met for dep_context=non-requeueable deps ti=<TaskInstance: ETL_Dag_S3.detect_new_or_changed_rows scheduled__2024-09-11T00:00:00+00:00 [queued]>
[2024-09-13T15:26:01.432+0000] {taskinstance.py:1956} INFO - Dependencies all met for dep_context=requeueable deps ti=<TaskInstance: ETL_Dag_S3.detect_new_or_changed_rows scheduled__2024-09-11T00:00:00+00:00 [queued]>
[2024-09-13T15:26:01.433+0000] {taskinstance.py:2170} INFO - Starting attempt 4 of 6
[2024-09-13T15:26:01.459+0000] {taskinstance.py:2191} INFO - Executing <Task(_PythonDecoratedOperator): detect_new_or_changed_rows> on 2024-09-11 00:00:00+00:00
[2024-09-13T15:26:01.471+0000] {standard_task_runner.py:60} INFO - Started process 236 to run task
[2024-09-13T15:26:01.481+0000] {standard_task_runner.py:87} INFO - Running: ['***', 'tasks', 'run', 'ETL_Dag_S3', 'detect_new_or_changed_rows', 'scheduled__2024-09-11T00:00:00+00:00', '--job-id', '13', '--raw', '--subdir', 'DAGS_FOLDER/etl_dag_s3.py', '--cfg-path', '/tmp/tmp4dqqg52n']
[2024-09-13T15:26:01.485+0000] {standard_task_runner.py:88} INFO - Job 13: Subtask detect_new_or_changed_rows
[2024-09-13T15:26:01.694+0000] {task_command.py:423} INFO - Running <TaskInstance: ETL_Dag_S3.detect_new_or_changed_rows scheduled__2024-09-11T00:00:00+00:00 [running]> on host f9589f9e7519
[2024-09-13T15:26:01.876+0000] {taskinstance.py:2480} INFO - Exporting env vars: AIRFLOW_CTX_DAG_OWNER='jasontran' AIRFLOW_CTX_DAG_ID='ETL_Dag_S3' AIRFLOW_CTX_TASK_ID='detect_new_or_changed_rows' AIRFLOW_CTX_EXECUTION_DATE='2024-09-11T00:00:00+00:00' AIRFLOW_CTX_TRY_NUMBER='4' AIRFLOW_CTX_DAG_RUN_ID='scheduled__2024-09-11T00:00:00+00:00'
[2024-09-13T15:26:02.742+0000] {taskinstance.py:2698} ERROR - Task failed with exception
Traceback (most recent call last):
  File "/home/airflow/.local/lib/python3.8/site-packages/airflow/models/taskinstance.py", line 433, in _execute_task
    result = execute_callable(context=context, **execute_callable_kwargs)
  File "/home/airflow/.local/lib/python3.8/site-packages/airflow/decorators/base.py", line 241, in execute
    return_value = super().execute(context)
  File "/home/airflow/.local/lib/python3.8/site-packages/airflow/operators/python.py", line 199, in execute
    return_value = self.execute_callable()
  File "/home/airflow/.local/lib/python3.8/site-packages/airflow/operators/python.py", line 216, in execute_callable
    return self.python_callable(*self.op_args, **self.op_kwargs)
  File "/opt/airflow/includes/emp_dim_insert_update.py", line 38, in detect_new_or_changed_rows
    obj = s3_client.get_object(Bucket='etl-airflow-bucket-demo', Key='Jason_emp_data.csv')
  File "/home/airflow/.local/lib/python3.8/site-packages/botocore/client.py", line 553, in _api_call
    return self._make_api_call(operation_name, kwargs)
  File "/home/airflow/.local/lib/python3.8/site-packages/botocore/client.py", line 989, in _make_api_call
    http, parsed_response = self._make_request(
  File "/home/airflow/.local/lib/python3.8/site-packages/botocore/client.py", line 1015, in _make_request
    return self._endpoint.make_request(operation_model, request_dict)
  File "/home/airflow/.local/lib/python3.8/site-packages/botocore/endpoint.py", line 119, in make_request
    return self._send_request(request_dict, operation_model)
  File "/home/airflow/.local/lib/python3.8/site-packages/botocore/endpoint.py", line 198, in _send_request
    request = self.create_request(request_dict, operation_model)
  File "/home/airflow/.local/lib/python3.8/site-packages/botocore/endpoint.py", line 134, in create_request
    self._event_emitter.emit(
  File "/home/airflow/.local/lib/python3.8/site-packages/botocore/hooks.py", line 412, in emit
    return self._emitter.emit(aliased_event_name, **kwargs)
  File "/home/airflow/.local/lib/python3.8/site-packages/botocore/hooks.py", line 256, in emit
    return self._emit(event_name, kwargs)
  File "/home/airflow/.local/lib/python3.8/site-packages/botocore/hooks.py", line 239, in _emit
    response = handler(**kwargs)
  File "/home/airflow/.local/lib/python3.8/site-packages/botocore/signers.py", line 105, in handler
    return self.sign(operation_name, request)
  File "/home/airflow/.local/lib/python3.8/site-packages/botocore/signers.py", line 195, in sign
    auth.add_auth(request)
  File "/home/airflow/.local/lib/python3.8/site-packages/botocore/auth.py", line 418, in add_auth
    raise NoCredentialsError()
botocore.exceptions.NoCredentialsError: Unable to locate credentials
[2024-09-13T15:26:02.858+0000] {taskinstance.py:1138} INFO - Marking task as UP_FOR_RETRY. dag_id=ETL_Dag_S3, task_id=detect_new_or_changed_rows, execution_date=20240911T000000, start_date=20240913T152601, end_date=20240913T152602
[2024-09-13T15:26:02.969+0000] {standard_task_runner.py:107} ERROR - Failed to execute job 13 for task detect_new_or_changed_rows (Unable to locate credentials; 236)
[2024-09-13T15:26:03.044+0000] {local_task_job_runner.py:234} INFO - Task exited with return code 1
[2024-09-13T15:26:03.097+0000] {taskinstance.py:3280} INFO - 0 downstream tasks scheduled from follow-on schedule check
