[2024-08-29T15:54:50.640+0000] {taskinstance.py:1956} INFO - Dependencies all met for dep_context=non-requeueable deps ti=<TaskInstance: ETL_Dag_S3.detect_new_or_changed_rows scheduled__2024-08-29T14:00:00+00:00 [queued]>
[2024-08-29T15:54:50.675+0000] {taskinstance.py:1956} INFO - Dependencies all met for dep_context=requeueable deps ti=<TaskInstance: ETL_Dag_S3.detect_new_or_changed_rows scheduled__2024-08-29T14:00:00+00:00 [queued]>
[2024-08-29T15:54:50.676+0000] {taskinstance.py:2170} INFO - Starting attempt 1 of 6
[2024-08-29T15:54:50.724+0000] {taskinstance.py:2191} INFO - Executing <Task(_PythonDecoratedOperator): detect_new_or_changed_rows> on 2024-08-29 14:00:00+00:00
[2024-08-29T15:54:50.736+0000] {standard_task_runner.py:60} INFO - Started process 1572 to run task
[2024-08-29T15:54:50.744+0000] {standard_task_runner.py:87} INFO - Running: ['***', 'tasks', 'run', 'ETL_Dag_S3', 'detect_new_or_changed_rows', 'scheduled__2024-08-29T14:00:00+00:00', '--job-id', '32', '--raw', '--subdir', 'DAGS_FOLDER/etl_dag_s3.py', '--cfg-path', '/tmp/tmpqjzyswq8']
[2024-08-29T15:54:50.748+0000] {standard_task_runner.py:88} INFO - Job 32: Subtask detect_new_or_changed_rows
[2024-08-29T15:54:50.869+0000] {task_command.py:423} INFO - Running <TaskInstance: ETL_Dag_S3.detect_new_or_changed_rows scheduled__2024-08-29T14:00:00+00:00 [running]> on host 3d8ae123b0e6
[2024-08-29T15:54:51.029+0000] {taskinstance.py:2480} INFO - Exporting env vars: AIRFLOW_CTX_DAG_OWNER='jasontran' AIRFLOW_CTX_DAG_ID='ETL_Dag_S3' AIRFLOW_CTX_TASK_ID='detect_new_or_changed_rows' AIRFLOW_CTX_EXECUTION_DATE='2024-08-29T14:00:00+00:00' AIRFLOW_CTX_TRY_NUMBER='1' AIRFLOW_CTX_DAG_RUN_ID='scheduled__2024-08-29T14:00:00+00:00'
[2024-08-29T15:54:51.215+0000] {taskinstance.py:2698} ERROR - Task failed with exception
Traceback (most recent call last):
  File "/home/airflow/.local/lib/python3.8/site-packages/fsspec/registry.py", line 236, in get_filesystem_class
    register_implementation(protocol, _import_class(bit["class"]))
  File "/home/airflow/.local/lib/python3.8/site-packages/fsspec/registry.py", line 271, in _import_class
    mod = importlib.import_module(mod)
  File "/usr/local/lib/python3.8/importlib/__init__.py", line 127, in import_module
    return _bootstrap._gcd_import(name[level:], package, level)
  File "<frozen importlib._bootstrap>", line 1014, in _gcd_import
  File "<frozen importlib._bootstrap>", line 991, in _find_and_load
  File "<frozen importlib._bootstrap>", line 973, in _find_and_load_unlocked
ModuleNotFoundError: No module named 's3fs'

The above exception was the direct cause of the following exception:

Traceback (most recent call last):
  File "/home/airflow/.local/lib/python3.8/site-packages/airflow/models/taskinstance.py", line 433, in _execute_task
    result = execute_callable(context=context, **execute_callable_kwargs)
  File "/home/airflow/.local/lib/python3.8/site-packages/airflow/decorators/base.py", line 241, in execute
    return_value = super().execute(context)
  File "/home/airflow/.local/lib/python3.8/site-packages/airflow/operators/python.py", line 199, in execute
    return_value = self.execute_callable()
  File "/home/airflow/.local/lib/python3.8/site-packages/airflow/operators/python.py", line 216, in execute_callable
    return self.python_callable(*self.op_args, **self.op_kwargs)
  File "/opt/airflow/includes/emp_dim_insert_update.py", line 19, in detect_new_or_changed_rows
    emp_detail = pd.read_csv('s3://etl-airflow-bucket-demo/Jason_emp_data.csv')
  File "/home/airflow/.local/lib/python3.8/site-packages/pandas/io/parsers/readers.py", line 912, in read_csv
    return _read(filepath_or_buffer, kwds)
  File "/home/airflow/.local/lib/python3.8/site-packages/pandas/io/parsers/readers.py", line 577, in _read
    parser = TextFileReader(filepath_or_buffer, **kwds)
  File "/home/airflow/.local/lib/python3.8/site-packages/pandas/io/parsers/readers.py", line 1407, in __init__
    self._engine = self._make_engine(f, self.engine)
  File "/home/airflow/.local/lib/python3.8/site-packages/pandas/io/parsers/readers.py", line 1661, in _make_engine
    self.handles = get_handle(
  File "/home/airflow/.local/lib/python3.8/site-packages/pandas/io/common.py", line 716, in get_handle
    ioargs = _get_filepath_or_buffer(
  File "/home/airflow/.local/lib/python3.8/site-packages/pandas/io/common.py", line 414, in _get_filepath_or_buffer
    file_obj = fsspec.open(
  File "/home/airflow/.local/lib/python3.8/site-packages/fsspec/core.py", line 459, in open
    out = open_files(
  File "/home/airflow/.local/lib/python3.8/site-packages/fsspec/core.py", line 283, in open_files
    fs, fs_token, paths = get_fs_token_paths(
  File "/home/airflow/.local/lib/python3.8/site-packages/fsspec/core.py", line 623, in get_fs_token_paths
    chain = _un_chain(urlpath0, storage_options or {})
  File "/home/airflow/.local/lib/python3.8/site-packages/fsspec/core.py", line 332, in _un_chain
    cls = get_filesystem_class(protocol)
  File "/home/airflow/.local/lib/python3.8/site-packages/fsspec/registry.py", line 238, in get_filesystem_class
    raise ImportError(bit["err"]) from e
ImportError: Install s3fs to access S3
[2024-08-29T15:54:51.244+0000] {taskinstance.py:1138} INFO - Marking task as UP_FOR_RETRY. dag_id=ETL_Dag_S3, task_id=detect_new_or_changed_rows, execution_date=20240829T140000, start_date=20240829T155450, end_date=20240829T155451
[2024-08-29T15:54:51.270+0000] {standard_task_runner.py:107} ERROR - Failed to execute job 32 for task detect_new_or_changed_rows (Install s3fs to access S3; 1572)
[2024-08-29T15:54:51.321+0000] {local_task_job_runner.py:234} INFO - Task exited with return code 1
[2024-08-29T15:54:51.361+0000] {taskinstance.py:3280} INFO - 0 downstream tasks scheduled from follow-on schedule check
